Workbook

Sheet 테스트 케이스
A1: POTATO SURVIVORS — QA 테스트 케이스
A2: 채워 넣을 칸: [실제 결과] [결과: Pass/Fail/N/A/보류 드롭다운] [비고]. 나머지는 명세이므로 수정하지 마세요. 결과는 '요약' 시트에서 자동 집계됩니다.
A3: TC ID | B3: 대분류 | C3: 테스트 항목 | D3: 사전조건 | E3: 테스트 절차 | F3: 기대 결과 | G3: 실제 결과 | H3: 결과 | I3: 비고
A4: 예시 | B4: 전투 | C4: 근접 자동공격 | D4: 근접 무기 장착·적 존재 | E4: 적이 감지 범위에 진입 | F4: 자동 스핀 공격으로 적에게 피해 | G4: 정상 작동함 | H4: Pass | I4: 프레임 드랍 없음
A5: TC-001 | B5: 로비 | C5: 게임 최초 실행 | D5: 게임을 처음 실행 | E5: 에디터/빌드로 게임 실행 | F5: MainMenu 씬이 먼저 표시(타이틀 로고·무기 6종·시작/종료 버튼) | G5: 정상 작동함 | H5: Pass
A6: TC-002 | B6: 로비 | C6: 무기 선택 | D6: 로비 화면 | E6: 무기 카드 클릭 | F6: 선택 카드가 노란색 하이라이트 + 하단에 선택 무기 정보 표시 | G6: 정상 작동함 | H6: Pass
A7: TC-003 | B7: 로비 | C7: 게임 시작 | D7: 무기 1개 선택 | E7: '게임 시작' 클릭 | F7: 게임 씬 진입 + 선택 무기를 장착한 상태로 시작 | G7: 정상 작동함 | H7: Pass
A8: TC-004 | B8: 로비 | C8: 무기 미선택 시작 | D8: 무기 미선택 | E8: '게임 시작' 클릭 | F8: 크래시 없이 시작(기본 무기 또는 빈손) | G8: 무기 미선택 불가 | H8: 보류 | I8: 무기를 안고르고 시작할 필요 x, 게임 시작시 기본 무기 클릭 시작
A9: TC-005 | B9: 로비 | C9: 종료 | D9: 로비 화면 | E9: '종료' 클릭 | F9: 게임 종료(에디터는 플레이 모드 중지) | G9: 정상 작동함 | H9: Pass
A10: TC-006 | B10: 이동 | C10: 기본 이동 | D10: 게임 진행 중 | E10: WASD/방향키 입력 | F10: 플레이어가 해당 방향으로 이동 | G10: 정상 작동함 | H10: Pass
A11: TC-007 | B11: 이동 | C11: 화면 경계 | D11: 플레이어를 화면 끝으로 | E11: 화면 밖으로 계속 이동 시도 | F11: 카메라 화면 경계를 벗어나지 않음 | G11: 작동 | H11: Fail | I11: 캐릭터 중심까지 이동, 캐릭터 절반 잘림
A12: TC-008 | B12: 전투 | C12: 근접 자동공격 | D12: 근접 무기 장착·적 존재 | E12: 적이 감지 범위에 진입 | F12: 무기가 자동 스핀 공격하여 적에게 피해 | G12: 정상 작동함 | H12: Pass
A13: TC-009 | B13: 전투 | C13: 원거리 발사 | D13: 원거리 무기 장착·적 존재 | E13: 적 감지 | F13: 투사체가 적 방향으로 발사되어 피해 | G13: 정상 작동함 | H13: Pass
A14: TC-010 | B14: 전투 | C14: 샷건 산탄 | D14: 샷건 장착 | E14: 공격 발동 | F14: 투사체 5발이 부채꼴로 발사 | G14: 정상 작동함 | H14: Pass
A15: TC-011 | B15: 전투 | C15: 쿨다운 | D15: 공격 직후 | E15: 쿨다운 시간 대기 | F15: 쿨다운 경과 후 다음 공격 발동 | G15: 정상 작동함 | H15: Pass
A16: TC-012 | B16: 전투 | C16: 적 없음 | D16: 주변에 적 없음 | E16: 대기 | F16: 무기가 공격하지 않음(투사체 낭비 없음) | G16: 정상 작동함 | H16: Pass
A17: TC-013 | B17: 전투 | C17: 관통 | D17: 관통 무기(석궁 등) | E17: 투사체가 적 명중 | F17: 지정 관통 수만큼 적을 통과하며 타격 | G17: 정상 작동함 | H17: Pass
A18: TC-014 | B18: 몬스터 | C18: 스폰 위치 | D18: 웨이브 시작 | E18: 웨이브 개시 | F18: 몬스터가 화면 안 영역에 스폰 | G18: 정상 작동함 | H18: Pass
A19: TC-015 | B19: 몬스터 | C19: 추격 | D19: 몬스터 스폰됨 | E19: 시간 경과 | F19: 몬스터가 플레이어를 추격 | G19: 정상 작동함 | H19: Pass
A20: TC-016 | B20: 몬스터 | C20: 근접 공격 | D20: 몬스터가 플레이어에 접촉 | E20: 접촉 유지 | F20: 플레이어 HP 감소 | G20: 정상 작동함 | H20: Pass
A21: TC-017 | B21: 몬스터 | C21: 원거리 몬스터 | D21: 원거리 몬스터 존재 | E21: 사거리 내 플레이어 | F21: 몬스터가 플레이어에게 투사체 발사(플레이어만 피격, 몬스터끼리 X) | G21: 정상 작동함 | H21: Pass
A22: TC-018 | B22: 보스 | C22: 등장 주기 | D22: 스테이지 진행 | E22: 5스테이지 도달 | F22: 보스가 등장(2라운드에는 안 나옴) | G22: 작동 x | H22: Fail | I22: 보스가 등장하지 않음
A23: TC-019 | B23: 몬스터 | C23: 처치 보상 | D23: 몬스터에 피해 누적 | E23: 몬스터 처치 | F23: 코인이 드랍됨 | G23: 정상 작동함 | H23: Pass
A24: TC-020 | B24: 웨이브 | C24: 시간 종료 | D24: 웨이브 진행 중 | E24: 20초 경과 | F24: 웨이브 종료 후 상점 오픈 | G24: 정상 작동함 | H24: Pass
A25: TC-021 | B25: 웨이브 | C25: 전멸 무관 | D25: 웨이브 진행 중 | E25: 시간 남은 채 모든 몬스터 처치 | F25: 웨이브가 끝나지 않고 계속 진행(시간 기반) | G25: 정상 작동함 | H25: Pass
A26: TC-022 | B26: 스테이지 | C26: 번호 증가 | D26: 상점 화면 | E26: '다음 라운드' 클릭 | F26: 스테이지 번호 +1 후 웨이브 재개 | G26: 정상 작동함 | H26: Pass
A27: TC-023 | B27: HP | C27: 체력바 감소 | D27: 플레이어 피격 | E27: 피해 받음 | F27: 머리 위 체력바가 감소 | G27: 정상 작동함 | H27: Pass
A28: TC-024 | B28: 사망 | C28: 게임오버 | D28: 플레이어 HP 0 | E28: HP가 0이 됨 | F28: 게임오버 패널 표시 + 게임 일시정지 | G28: 정상 작동함 | H28: Pass
A29: TC-025 | B29: 게임오버 | C29: 재시작 | D29: 게임오버 패널 | E29: '다시 시작' 클릭 | F29: 현재 씬 리로드(초기화) + 시작 무기 재지급 | G29: 정상 작동함 | H29: Pass
A30: TC-026 | B30: 게임오버 | C30: 로비 복귀 | D30: 게임오버 패널 | E30: '로비로' 클릭 | F30: MainMenu 복귀 + 시작 무기 선택 초기화 | G30: 정상 작동함 | H30: Pass
A31: TC-027 | B31: 코인 | C31: 드랍 | D31: 몬스터 처치 | E31: 처치 발생 | F31: 코인이 바닥에 드랍 | G31: 정상 작동함 | H31: Pass
A32: TC-028 | B32: 코인 | C32: 자석 획득 | D32: 코인 드랍됨 | E32: 플레이어가 코인에 접근 | F32: 코인이 흡수되어 골드 증가 | G32: 작동 x | H32: Fail | I32: 자석 등장 x
A33: TC-029 | B33: 코인 | C33: HUD 갱신 | D33: 코인 획득 | E33: 골드 증가 | F33: HUD 골드 수치가 즉시 갱신 | G33: 정상 작동함 | H33: Pass
A34: TC-030 | B34: 상점 | C34: 자동 오픈 | D34: 웨이브 종료 | E34: 종료 시점 | F34: 상점 자동으로 열리고 게임 일시정지 | G34: 정상 작동함 | H34: Pass
A35: TC-031 | B35: 상점 | C35: 신규 표시 | D35: 안 가진 무기가 카드에 뜸 | E35: 카드 확인 | F35: '무기명 Lv1 (신규)'로 표시 | G35: 정상 작동함 | H35: Pass
A36: TC-032 | B36: 상점 | C36: 강화 표시 | D36: 보유 무기가 카드에 뜸 | E36: 카드 확인 | F36: '무기명 Lv(현재+1) (강화)'로 표시 | G36: 정상 작동함 | H36: Pass
A37: TC-033 | B37: 상점 | C37: 만렙 제외 | D37: 특정 무기 Lv5 보유 | E37: 상점 여러 번 확인 | F37: 해당 무기가 카드에 뜨지 않음 | G37: 정상 작동함
A38: TC-034 | B38: 상점 | C38: 무기 구매 | D38: 골드 충분·무기 카드 | E38: 카드 구매 | F38: 무기 장착 또는 레벨업 + 골드 차감 | G38: 정상 작동함 | H38: Pass
A39: TC-035 | B39: 상점 | C39: 골드 부족 | D39: 골드 < 가격 | E39: 카드 확인 | F39: 구매 버튼 비활성(구매 불가) | G39: 정상 작동함 | H39: Pass
A40: TC-036 | B40: 상점 | C40: 슬롯 만석 | D40: 6슬롯 가득 + 신규 무기 | E40: 구매 시도 | F40: 구매 실패 + 골드 환불 | G40: 정상 작동함 | H40: Pass
...

Sheet 요약
A1: 테스트 요약 | D1: 대분류별 케이스 수
D2: 대분류 | E2: 개수
A3: 전체 케이스 | B3: =COUNTA('테스트 케이스'!A5:A59) -> 55 | D3: 로비 | E3: =COUNTIF('테스트 케이스'!B5:B59,D3) -> 5
A4: Pass | B4: =COUNTIF('테스트 케이스'!H5:H59,"Pass") -> 47 | D4: 이동 | E4: =COUNTIF('테스트 케이스'!B5:B59,D4) -> 2
A5: Fail | B5: =COUNTIF('테스트 케이스'!H5:H59,"Fail") -> 6 | D5: 전투 | E5: =COUNTIF('테스트 케이스'!B5:B59,D5) -> 6
A6: N/A | B6: =COUNTIF('테스트 케이스'!H5:H59,"N/A") -> 0 | D6: 몬스터 | E6: =COUNTIF('테스트 케이스'!B5:B59,D6) -> 5
A7: 보류 | B7: =COUNTIF('테스트 케이스'!H5:H59,"보류") -> 1 | D7: 보스 | E7: =COUNTIF('테스트 케이스'!B5:B59,D7) -> 1
A8: 미실행 | B8: =COUNTA('테스트 케이스'!A5:A59)-COUNTA('테스트 케이스'!H5:H59) -> 1 | D8: 웨이브 | E8: =COUNTIF('테스트 케이스'!B5:B59,D8) -> 2
D9: 스테이지 | E9: =COUNTIF('테스트 케이스'!B5:B59,D9) -> 1
D10: HP | E10: =COUNTIF('테스트 케이스'!B5:B59,D10) -> 1
A11: 진행률(Pass/전체) | B11: =IF(B3=0,0,B4/B3) -> 0.85454545 | D11: 사망 | E11: =COUNTIF('테스트 케이스'!B5:B59,D11) -> 1
D12: 게임오버 | E12: =COUNTIF('테스트 케이스'!B5:B59,D12) -> 2
D13: 코인 | E13: =COUNTIF('테스트 케이스'!B5:B59,D13) -> 3
D14: 상점 | E14: =COUNTIF('테스트 케이스'!B5:B59,D14) -> 16
D15: 세트 | E15: =COUNTIF('테스트 케이스'!B5:B59,D15) -> 4
D16: HUD | E16: =COUNTIF('테스트 케이스'!B5:B59,D16) -> 3
D17: 아이콘 | E17: =COUNTIF('테스트 케이스'!B5:B59,D17) -> 2
D18: 무기 | E18: =COUNTIF('테스트 케이스'!B5:B59,D18) -> 1
